INFO:root:aliahmadsdasdsad5szhsdssdssssssssssssss
INFO:root:26a22b29-3611-40ce-87c2-6641e3a1e8ac
ERROR:django.request:Internal Server Error: /buyer/
Traceback (most recent call last):
  File "/home/ashir/anaconda3/envs/e-commerce/lib/python3.10/site-packages/django/core/handlers/exception.py", line 47, in inner
    response = get_response(request)
  File "/home/ashir/anaconda3/envs/e-commerce/lib/python3.10/site-packages/django/core/handlers/base.py", line 181, in _get_response
    response = wrapped_callback(request, *callback_args, **callback_kwargs)
  File "/home/ashir/anaconda3/envs/e-commerce/lib/python3.10/site-packages/django/views/decorators/csrf.py", line 54, in wrapped_view
    return view_func(*args, **kwargs)
  File "/home/ashir/anaconda3/envs/e-commerce/lib/python3.10/site-packages/django/views/generic/base.py", line 69, in view
    return self.dispatch(request, *args, **kwargs)
  File "/home/ashir/anaconda3/envs/e-commerce/lib/python3.10/site-packages/rest_framework/views.py", line 509, in dispatch
    response = self.handle_exception(exc)
  File "/home/ashir/anaconda3/envs/e-commerce/lib/python3.10/site-packages/rest_framework/views.py", line 469, in handle_exception
    self.raise_uncaught_exception(exc)
  File "/home/ashir/anaconda3/envs/e-commerce/lib/python3.10/site-packages/rest_framework/views.py", line 480, in raise_uncaught_exception
    raise exc
  File "/home/ashir/anaconda3/envs/e-commerce/lib/python3.10/site-packages/rest_framework/views.py", line 506, in dispatch
    response = handler(request, *args, **kwargs)
  File "/home/ashir/PycharmProjects/e-commerce/Buyer/views.py", line 41, in post
    'access': str(RefreshToken.for_user(Buyer.objects.get(id=buyer.id)).access_token), "Msg": "Buyer Created Successfully"},
  File "/home/ashir/anaconda3/envs/e-commerce/lib/python3.10/site-packages/rest_framework_simplejwt/tokens.py", line 192, in for_user
    logging.info(f"{token.key()}")
AttributeError: 'RefreshToken' object has no attribute 'key'
INFO:django.utils.autoreload:/home/ashir/anaconda3/envs/e-commerce/lib/python3.10/site-packages/rest_framework_simplejwt/tokens.py changed, reloading.
INFO:root:aliahmadsdasdsad5szhsdssdsssssssssssssss
INFO:root:2f94e3ee-15af-468d-8ea2-d2adcaff4398
ERROR:django.request:Internal Server Error: /buyer/
Traceback (most recent call last):
  File "/home/ashir/anaconda3/envs/e-commerce/lib/python3.10/site-packages/django/core/handlers/exception.py", line 47, in inner
    response = get_response(request)
  File "/home/ashir/anaconda3/envs/e-commerce/lib/python3.10/site-packages/django/core/handlers/base.py", line 181, in _get_response
    response = wrapped_callback(request, *callback_args, **callback_kwargs)
  File "/home/ashir/anaconda3/envs/e-commerce/lib/python3.10/site-packages/django/views/decorators/csrf.py", line 54, in wrapped_view
    return view_func(*args, **kwargs)
  File "/home/ashir/anaconda3/envs/e-commerce/lib/python3.10/site-packages/django/views/generic/base.py", line 69, in view
    return self.dispatch(request, *args, **kwargs)
  File "/home/ashir/anaconda3/envs/e-commerce/lib/python3.10/site-packages/rest_framework/views.py", line 509, in dispatch
    response = self.handle_exception(exc)
  File "/home/ashir/anaconda3/envs/e-commerce/lib/python3.10/site-packages/rest_framework/views.py", line 469, in handle_exception
    self.raise_uncaught_exception(exc)
  File "/home/ashir/anaconda3/envs/e-commerce/lib/python3.10/site-packages/rest_framework/views.py", line 480, in raise_uncaught_exception
    raise exc
  File "/home/ashir/anaconda3/envs/e-commerce/lib/python3.10/site-packages/rest_framework/views.py", line 506, in dispatch
    response = handler(request, *args, **kwargs)
  File "/home/ashir/PycharmProjects/e-commerce/Buyer/views.py", line 41, in post
    'access': str(RefreshToken.for_user(Buyer.objects.get(id=buyer.id)).access_token), "Msg": "Buyer Created Successfully"},
  File "/home/ashir/anaconda3/envs/e-commerce/lib/python3.10/site-packages/rest_framework_simplejwt/tokens.py", line 192, in for_user
    logging.info(f"{token.values()}")
AttributeError: 'RefreshToken' object has no attribute 'values'
INFO:django.utils.autoreload:/home/ashir/anaconda3/envs/e-commerce/lib/python3.10/site-packages/rest_framework_simplejwt/tokens.py changed, reloading.
INFO:root:aliahmadsdasdsad5szhsdssdssssssssssssssss
INFO:root:d9934aa9-b4bb-4991-bf3a-e3efa118ac42
ERROR:django.request:Internal Server Error: /buyer/
Traceback (most recent call last):
  File "/home/ashir/anaconda3/envs/e-commerce/lib/python3.10/site-packages/django/core/handlers/exception.py", line 47, in inner
    response = get_response(request)
  File "/home/ashir/anaconda3/envs/e-commerce/lib/python3.10/site-packages/django/core/handlers/base.py", line 181, in _get_response
    response = wrapped_callback(request, *callback_args, **callback_kwargs)
  File "/home/ashir/anaconda3/envs/e-commerce/lib/python3.10/site-packages/django/views/decorators/csrf.py", line 54, in wrapped_view
    return view_func(*args, **kwargs)
  File "/home/ashir/anaconda3/envs/e-commerce/lib/python3.10/site-packages/django/views/generic/base.py", line 69, in view
    return self.dispatch(request, *args, **kwargs)
  File "/home/ashir/anaconda3/envs/e-commerce/lib/python3.10/site-packages/rest_framework/views.py", line 509, in dispatch
    response = self.handle_exception(exc)
  File "/home/ashir/anaconda3/envs/e-commerce/lib/python3.10/site-packages/rest_framework/views.py", line 469, in handle_exception
    self.raise_uncaught_exception(exc)
  File "/home/ashir/anaconda3/envs/e-commerce/lib/python3.10/site-packages/rest_framework/views.py", line 480, in raise_uncaught_exception
    raise exc
  File "/home/ashir/anaconda3/envs/e-commerce/lib/python3.10/site-packages/rest_framework/views.py", line 506, in dispatch
    response = handler(request, *args, **kwargs)
  File "/home/ashir/PycharmProjects/e-commerce/Buyer/views.py", line 41, in post
    'access': str(RefreshToken.for_user(Buyer.objects.get(id=buyer.id)).access_token), "Msg": "Buyer Created Successfully"},
  File "/home/ashir/anaconda3/envs/e-commerce/lib/python3.10/site-packages/rest_framework_simplejwt/tokens.py", line 192, in for_user
    logging.info(f"{token.access_key}")
AttributeError: 'RefreshToken' object has no attribute 'access_key'
INFO:django.utils.autoreload:/home/ashir/anaconda3/envs/e-commerce/lib/python3.10/site-packages/rest_framework_simplejwt/tokens.py changed, reloading.
INFO:root:aliahmadsdasdsad5szhsdssdsssssssssssssssss
INFO:root:09dfa673-cf9c-4285-a687-c2bd0bab9709
INFO:root:None
INFO:django.utils.autoreload:/home/ashir/PycharmProjects/e-commerce/ecommerce/settings.py changed, reloading.
INFO:django.utils.autoreload:/home/ashir/PycharmProjects/e-commerce/Buyer/views.py changed, reloading.
INFO:root:aliahmadsdasdsad5szhsdssdssssssssssssssssss
INFO:root:2c682c75-8066-4146-b23a-ff7200e3e7cf
INFO:root:None
ERROR:django.request:Internal Server Error: /buyer/
Traceback (most recent call last):
  File "/home/ashir/anaconda3/envs/e-commerce/lib/python3.10/site-packages/django/core/handlers/exception.py", line 47, in inner
    response = get_response(request)
  File "/home/ashir/anaconda3/envs/e-commerce/lib/python3.10/site-packages/django/core/handlers/base.py", line 204, in _get_response
    response = response.render()
  File "/home/ashir/anaconda3/envs/e-commerce/lib/python3.10/site-packages/django/template/response.py", line 105, in render
    self.content = self.rendered_content
  File "/home/ashir/anaconda3/envs/e-commerce/lib/python3.10/site-packages/rest_framework/response.py", line 70, in rendered_content
    ret = renderer.render(self.data, accepted_media_type, context)
  File "/home/ashir/anaconda3/envs/e-commerce/lib/python3.10/site-packages/rest_framework/renderers.py", line 100, in render
    ret = json.dumps(
  File "/home/ashir/anaconda3/envs/e-commerce/lib/python3.10/site-packages/rest_framework/utils/json.py", line 25, in dumps
    return json.dumps(*args, **kwargs)
  File "/home/ashir/anaconda3/envs/e-commerce/lib/python3.10/json/__init__.py", line 238, in dumps
    **kw).encode(obj)
  File "/home/ashir/anaconda3/envs/e-commerce/lib/python3.10/json/encoder.py", line 199, in encode
    chunks = self.iterencode(o, _one_shot=True)
  File "/home/ashir/anaconda3/envs/e-commerce/lib/python3.10/json/encoder.py", line 257, in iterencode
    return _iterencode(o, 0)
  File "/home/ashir/anaconda3/envs/e-commerce/lib/python3.10/site-packages/rest_framework/utils/encoders.py", line 67, in default
    return super().default(obj)
  File "/home/ashir/anaconda3/envs/e-commerce/lib/python3.10/json/encoder.py", line 179, in default
    raise TypeError(f'Object of type {o.__class__.__name__} '
TypeError: Object of type RefreshToken is not JSON serializable
INFO:django.utils.autoreload:/home/ashir/PycharmProjects/e-commerce/Buyer/views.py changed, reloading.
ERROR:django.request:Internal Server Error: /buyer/
INFO:root:aliahmadsdasdsad5szhsdssdsssssssssssssssssssss
INFO:root:c8e85a14-ba97-4a7d-81ff-706c9c4d3514
INFO:root:None
INFO:django.utils.autoreload:/home/ashir/PycharmProjects/e-commerce/Buyer/views.py changed, reloading.
INFO:root:aliahmadsdasdsad5szhsdssdssssssssssssssssssssss
INFO:root:f9508024-b919-48c1-9df6-07f7c4e42d17
INFO:root:None
ERROR:django.request:Internal Server Error: /buyer/
Traceback (most recent call last):
  File "/home/ashir/anaconda3/envs/e-commerce/lib/python3.10/site-packages/django/core/handlers/exception.py", line 47, in inner
    response = get_response(request)
  File "/home/ashir/anaconda3/envs/e-commerce/lib/python3.10/site-packages/django/core/handlers/base.py", line 181, in _get_response
    response = wrapped_callback(request, *callback_args, **callback_kwargs)
  File "/home/ashir/anaconda3/envs/e-commerce/lib/python3.10/site-packages/django/views/decorators/csrf.py", line 54, in wrapped_view
    return view_func(*args, **kwargs)
  File "/home/ashir/anaconda3/envs/e-commerce/lib/python3.10/site-packages/django/views/generic/base.py", line 69, in view
    return self.dispatch(request, *args, **kwargs)
  File "/home/ashir/anaconda3/envs/e-commerce/lib/python3.10/site-packages/rest_framework/views.py", line 509, in dispatch
    response = self.handle_exception(exc)
  File "/home/ashir/anaconda3/envs/e-commerce/lib/python3.10/site-packages/rest_framework/views.py", line 469, in handle_exception
    self.raise_uncaught_exception(exc)
  File "/home/ashir/anaconda3/envs/e-commerce/lib/python3.10/site-packages/rest_framework/views.py", line 480, in raise_uncaught_exception
    raise exc
  File "/home/ashir/anaconda3/envs/e-commerce/lib/python3.10/site-packages/rest_framework/views.py", line 506, in dispatch
    response = handler(request, *args, **kwargs)
  File "/home/ashir/PycharmProjects/e-commerce/Buyer/views.py", line 45, in post
    token = RefreshToken.for_user(buyer).access_key
AttributeError: 'RefreshToken' object has no attribute 'access_key'
INFO:django.utils.autoreload:/home/ashir/PycharmProjects/e-commerce/Buyer/views.py changed, reloading.
INFO:root:aliahmadsdasdsad5szhsdssdsssssssssssssssssssssss
INFO:root:355da095-8d02-46c1-b6a3-976b760ef50e
INFO:root:None
ERROR:django.request:Internal Server Error: /buyer/
Traceback (most recent call last):
  File "/home/ashir/anaconda3/envs/e-commerce/lib/python3.10/site-packages/django/core/handlers/exception.py", line 47, in inner
    response = get_response(request)
  File "/home/ashir/anaconda3/envs/e-commerce/lib/python3.10/site-packages/django/core/handlers/base.py", line 181, in _get_response
    response = wrapped_callback(request, *callback_args, **callback_kwargs)
  File "/home/ashir/anaconda3/envs/e-commerce/lib/python3.10/site-packages/django/views/decorators/csrf.py", line 54, in wrapped_view
    return view_func(*args, **kwargs)
  File "/home/ashir/anaconda3/envs/e-commerce/lib/python3.10/site-packages/django/views/generic/base.py", line 69, in view
    return self.dispatch(request, *args, **kwargs)
  File "/home/ashir/anaconda3/envs/e-commerce/lib/python3.10/site-packages/rest_framework/views.py", line 509, in dispatch
    response = self.handle_exception(exc)
  File "/home/ashir/anaconda3/envs/e-commerce/lib/python3.10/site-packages/rest_framework/views.py", line 469, in handle_exception
    self.raise_uncaught_exception(exc)
  File "/home/ashir/anaconda3/envs/e-commerce/lib/python3.10/site-packages/rest_framework/views.py", line 480, in raise_uncaught_exception
    raise exc
  File "/home/ashir/anaconda3/envs/e-commerce/lib/python3.10/site-packages/rest_framework/views.py", line 506, in dispatch
    response = handler(request, *args, **kwargs)
  File "/home/ashir/PycharmProjects/e-commerce/Buyer/views.py", line 45, in post
    token = RefreshToken.for_user(buyer).access_key()
AttributeError: 'RefreshToken' object has no attribute 'access_key'
INFO:django.utils.autoreload:/home/ashir/PycharmProjects/e-commerce/Buyer/views.py changed, reloading.
ERROR:django.request:Internal Server Error: /buyer/
INFO:root:aliahmadsdasdsad5szhsdssdssssssssssssssssssssssss
INFO:root:dc4acf85-0087-4a4e-8406-cc1867b49c22
INFO:root:None
INFO:django.utils.autoreload:/home/ashir/PycharmProjects/e-commerce/Buyer/views.py changed, reloading.
INFO:root:aliahmad
INFO:root:7cabfec6-fa7d-4e0e-b2fe-9c4c48ca7acf
INFO:root:None
